Workbook

Sheet 3-Level Bifurcation
A1: CFI · AOP 2026–27 · 3-level bifurcation (Vertical › Activity › Sub-Activity · ₹6.0 Cr)
A2: Particulars | B2: Level | C2: Budget (₹) | D2: In lacs | E2: % of AOP
A3: TOTAL — Annual Operating Plan 2026–27 | C3: =SUM('Line Items'!$F$3:$F$175) | D3: =C3/100000 | E3: =C3/$C$3
A4: Policy | B4: Vertical | C4: =SUMIF('Line Items'!$A$3:$A$175,$G4,'Line Items'!$F$3:$F$175) | D4: =C4/100000 | E4: =C4/$C$3 | G4: Policy
A5: Legal Resources for Victims in Vernacular Languages | B5: Activity | C5: =SUMIFS('Line Items'!$F$3:$F$175,'Line Items'!$A$3:$A$175,$G5,'Line Items'!$B$3:$B$175,$H5) | D5: =C5/100000 | E5: =C5/$C$3 | G5: Policy | H5: Legal Resources for Victims in Vernacular Languages
A6: Part 1: Development of Legal Resource Guide | B6: Sub-activity | C6: =SUMIFS('Line Items'!$F$3:$F$175,'Line Items'!$A$3:$A$175,$G6,'Line Items'!$B$3:$B$175,$H6,'Line Items'!$C$3:$C$175,$I6) | D6: =C6/100000 | G6: Policy | H6: Legal Resources for Victims in Vernacular Languages | I6: Part 1: Development of Legal Resource Guide
A7: Part 2: Outreach and Distribution | B7: Sub-activity | C7: =SUMIFS('Line Items'!$F$3:$F$175,'Line Items'!$A$3:$A$175,$G7,'Line Items'!$B$3:$B$175,$H7,'Line Items'!$C$3:$C$175,$I7) | D7: =C7/100000 | G7: Policy | H7: Legal Resources for Victims in Vernacular Languages | I7: Part 2: Outreach and Distribution
A8: Part 3: Awareness Workshops & Law Camps | B8: Sub-activity | C8: =SUMIFS('Line Items'!$F$3:$F$175,'Line Items'!$A$3:$A$175,$G8,'Line Items'!$B$3:$B$175,$H8,'Line Items'!$C$3:$C$175,$I8) | D8: =C8/100000 | G8: Policy | H8: Legal Resources for Victims in Vernacular Languages | I8: Part 3: Awareness Workshops & Law Camps
A9: Strengthening Road Safety Regulations via RTI/PIL | B9: Activity | C9: =SUMIFS('Line Items'!$F$3:$F$175,'Line Items'!$A$3:$A$175,$G9,'Line Items'!$B$3:$B$175,$H9) | D9: =C9/100000 | E9: =C9/$C$3 | G9: Policy | H9: Strengthening Road Safety Regulations via RTI/PIL
A10: Part 1: Policy ecosystem mapping in India | B10: Sub-activity | C10: =SUMIFS('Line Items'!$F$3:$F$175,'Line Items'!$A$3:$A$175,$G10,'Line Items'!$B$3:$B$175,$H10,'Line Items'!$C$3:$C$175,$I10) | D10: =C10/100000 | G10: Policy | H10: Strengthening Road Safety Regulations via RTI/PIL | I10: Part 1: Policy ecosystem mapping in India
A11: Part 2: Policy ideathon in law universities | B11: Sub-activity | C11: =SUMIFS('Line Items'!$F$3:$F$175,'Line Items'!$A$3:$A$175,$G11,'Line Items'!$B$3:$B$175,$H11,'Line Items'!$C$3:$C$175,$I11) | D11: =C11/100000 | G11: Policy | H11: Strengthening Road Safety Regulations via RTI/PIL | I11: Part 2: Policy ideathon in law universities
A12: Part 3: Primary Research – Cashless Treatment & Compensation | B12: Sub-activity | C12: =SUMIFS('Line Items'!$F$3:$F$175,'Line Items'!$A$3:$A$175,$G12,'Line Items'!$B$3:$B$175,$H12,'Line Items'!$C$3:$C$175,$I12) | D12: =C12/100000 | G12: Policy | H12: Strengthening Road Safety Regulations via RTI/PIL | I12: Part 3: Primary Research – Cashless Treatment & Compensation
A13: Infrastructure | B13: Vertical | C13: =SUMIF('Line Items'!$A$3:$A$175,$G13,'Line Items'!$F$3:$F$175) | D13: =C13/100000 | E13: =C13/$C$3 | G13: Infrastructure
A14: Infrastructure Internship and School Safety Zone | B14: Activity | C14: =SUMIFS('Line Items'!$F$3:$F$175,'Line Items'!$A$3:$A$175,$G14,'Line Items'!$B$3:$B$175,$H14) | D14: =C14/100000 | E14: =C14/$C$3 | G14: Infrastructure | H14: Infrastructure Internship and School Safety Zone
A15: 1. Infrastructure Internship | B15: Sub-activity | C15: =SUMIFS('Line Items'!$F$3:$F$175,'Line Items'!$A$3:$A$175,$G15,'Line Items'!$B$3:$B$175,$H15,'Line Items'!$C$3:$C$175,$I15) | D15: =C15/100000 | G15: Infrastructure | H15: Infrastructure Internship and School Safety Zone | I15: 1. Infrastructure Internship
A16: 2. Government Engagement & Advocacy | B16: Sub-activity | C16: =SUMIFS('Line Items'!$F$3:$F$175,'Line Items'!$A$3:$A$175,$G16,'Line Items'!$B$3:$B$175,$H16,'Line Items'!$C$3:$C$175,$I16) | D16: =C16/100000 | G16: Infrastructure | H16: Infrastructure Internship and School Safety Zone | I16: 2. Government Engagement & Advocacy
A17: 3. Safe School Zone – Pilots | B17: Sub-activity | C17: =SUMIFS('Line Items'!$F$3:$F$175,'Line Items'!$A$3:$A$175,$G17,'Line Items'!$B$3:$B$175,$H17,'Line Items'!$C$3:$C$175,$I17) | D17: =C17/100000 | G17: Infrastructure | H17: Infrastructure Internship and School Safety Zone | I17: 3. Safe School Zone – Pilots
A18: Technology | B18: Vertical | C18: =SUMIF('Line Items'!$A$3:$A$175,$G18,'Line Items'!$F$3:$F$175) | D18: =C18/100000 | E18: =C18/$C$3 | G18: Technology
A19: Collaboration with Google to influence user behaviour using maps | B19: Activity | C19: =SUMIFS('Line Items'!$F$3:$F$175,'Line Items'!$A$3:$A$175,$G19,'Line Items'!$B$3:$B$175,$H19) | D19: =C19/100000 | E19: =C19/$C$3 | G19: Technology | H19: Collaboration with Google to influence user behaviour using maps
A20: 1. Research, Behavour mapping and data preparation | B20: Sub-activity | C20: =SUMIFS('Line Items'!$F$3:$F$175,'Line Items'!$A$3:$A$175,$G20,'Line Items'!$B$3:$B$175,$H20,'Line Items'!$C$3:$C$175,$I20) | D20: =C20/100000 | G20: Technology | H20: Collaboration with Google to influence user behaviour using maps | I20: 1. Research, Behavour mapping and data preparation
A21: 2. Nudge & Messaging Strategy | B21: Sub-activity | C21: =SUMIFS('Line Items'!$F$3:$F$175,'Line Items'!$A$3:$A$175,$G21,'Line Items'!$B$3:$B$175,$H21,'Line Items'!$C$3:$C$175,$I21) | D21: =C21/100000 | G21: Technology | H21: Collaboration with Google to influence user behaviour using maps | I21: 2. Nudge & Messaging Strategy
A22: 3. Coordination & Liaison with Google | B22: Sub-activity | C22: =SUMIFS('Line Items'!$F$3:$F$175,'Line Items'!$A$3:$A$175,$G22,'Line Items'!$B$3:$B$175,$H22,'Line Items'!$C$3:$C$175,$I22) | D22: =C22/100000 | G22: Technology | H22: Collaboration with Google to influence user behaviour using maps | I22: 3. Coordination & Liaison with Google
A23: Community Action via Mobile App | B23: Activity | C23: =SUMIFS('Line Items'!$F$3:$F$175,'Line Items'!$A$3:$A$175,$G23,'Line Items'!$B$3:$B$175,$H23) | D23: =C23/100000 | E23: =C23/$C$3 | G23: Technology | H23: Community Action via Mobile App
A24: 1. App Features – Strategy & Coordination | B24: Sub-activity | C24: =SUMIFS('Line Items'!$F$3:$F$175,'Line Items'!$A$3:$A$175,$G24,'Line Items'!$B$3:$B$175,$H24,'Line Items'!$C$3:$C$175,$I24) | D24: =C24/100000 | G24: Technology | H24: Community Action via Mobile App | I24: 1. App Features – Strategy & Coordination
A25: 2. Liasioning for data | B25: Sub-activity | C25: =SUMIFS('Line Items'!$F$3:$F$175,'Line Items'!$A$3:$A$175,$G25,'Line Items'!$B$3:$B$175,$H25,'Line Items'!$C$3:$C$175,$I25) | D25: =C25/100000 | G25: Technology | H25: Community Action via Mobile App | I25: 2. Liasioning for data
A26: 3. Content & Storytelling | B26: Sub-activity | C26: =SUMIFS('Line Items'!$F$3:$F$175,'Line Items'!$A$3:$A$175,$G26,'Line Items'!$B$3:$B$175,$H26,'Line Items'!$C$3:$C$175,$I26) | D26: =C26/100000 | G26: Technology | H26: Community Action via Mobile App | I26: 3. Content & Storytelling
A27: 4. Incentives & Recognition | B27: Sub-activity | C27: =SUMIFS('Line Items'!$F$3:$F$175,'Line Items'!$A$3:$A$175,$G27,'Line Items'!$B$3:$B$175,$H27,'Line Items'!$C$3:$C$175,$I27) | D27: =C27/100000 | G27: Technology | H27: Community Action via Mobile App | I27: 4. Incentives & Recognition
A28: 5. Marketing & Promotional Outreach | B28: Sub-activity | C28: =SUMIFS('Line Items'!$F$3:$F$175,'Line Items'!$A$3:$A$175,$G28,'Line Items'!$B$3:$B$175,$H28,'Line Items'!$C$3:$C$175,$I28) | D28: =C28/100000 | G28: Technology | H28: Community Action via Mobile App | I28: 5. Marketing & Promotional Outreach
A29: National Level Road Safety International Hackathon (Marketing activity / Promoting use of tech of road safety) | B29: Activity | C29: =SUMIFS('Line Items'!$F$3:$F$175,'Line Items'!$A$3:$A$175,$G29,'Line Items'!$B$3:$B$175,$H29) | D29: =C29/100000 | E29: =C29/$C$3 | G29: Technology | H29: National Level Road Safety International Hackathon (Marketing activity / Promoting use of tech of road safety)
A30: 1. Pre-Hackathon Planning & Outreach | B30: Sub-activity | C30: =SUMIFS('Line Items'!$F$3:$F$175,'Line Items'!$A$3:$A$175,$G30,'Line Items'!$B$3:$B$175,$H30,'Line Items'!$C$3:$C$175,$I30) | D30: =C30/100000 | G30: Technology | H30: National Level Road Safety International Hackathon (Marketing activity / Promoting use of tech of road safety) | I30: 1. Pre-Hackathon Planning & Outreach
A31: 2. Zonal Hackathons (2 IITs) | B31: Sub-activity | C31: =SUMIFS('Line Items'!$F$3:$F$175,'Line Items'!$A$3:$A$175,$G31,'Line Items'!$B$3:$B$175,$H31,'Line Items'!$C$3:$C$175,$I31) | D31: =C31/100000 | G31: Technology | H31: National Level Road Safety International Hackathon (Marketing activity / Promoting use of tech of road safety) | I31: 2. Zonal Hackathons (2 IITs)
A32: 3. Grand Finale – National Event | B32: Sub-activity | C32: =SUMIFS('Line Items'!$F$3:$F$175,'Line Items'!$A$3:$A$175,$G32,'Line Items'!$B$3:$B$175,$H32,'Line Items'!$C$3:$C$175,$I32) | D32: =C32/100000 | G32: Technology | H32: National Level Road Safety International Hackathon (Marketing activity / Promoting use of tech of road safety) | I32: 3. Grand Finale – National Event
A33: 4. Prizes & Recognition | B33: Sub-activity | C33: =SUMIFS('Line Items'!$F$3:$F$175,'Line Items'!$A$3:$A$175,$G33,'Line Items'!$B$3:$B$175,$H33,'Line Items'!$C$3:$C$175,$I33) | D33: =C33/100000 | G33: Technology | H33: National Level Road Safety International Hackathon (Marketing activity / Promoting use of tech of road safety) | I33: 4. Prizes & Recognition
A34: 5. Documentation & Post-Event | B34: Sub-activity | C34: =SUMIFS('Line Items'!$F$3:$F$175,'Line Items'!$A$3:$A$175,$G34,'Line Items'!$B$3:$B$175,$H34,'Line Items'!$C$3:$C$175,$I34) | D34: =C34/100000 | G34: Technology | H34: National Level Road Safety International Hackathon (Marketing activity / Promoting use of tech of road safety) | I34: 5. Documentation & Post-Event
A35: Safety API | B35: Activity | C35: =SUMIFS('Line Items'!$F$3:$F$175,'Line Items'!$A$3:$A$175,$G35,'Line Items'!$B$3:$B$175,$H35) | D35: =C35/100000 | E35: =C35/$C$3 | G35: Technology | H35: Safety API
A36: 1. Product Strategy, User research | B36: Sub-activity | C36: =SUMIFS('Line Items'!$F$3:$F$175,'Line Items'!$A$3:$A$175,$G36,'Line Items'!$B$3:$B$175,$H36,'Line Items'!$C$3:$C$175,$I36) | D36: =C36/100000 | G36: Technology | H36: Safety API | I36: 1. Product Strategy, User research
A37: 2. Driving Behavior & Risk Modeling | B37: Sub-activity | C37: =SUMIFS('Line Items'!$F$3:$F$175,'Line Items'!$A$3:$A$175,$G37,'Line Items'!$B$3:$B$175,$H37,'Line Items'!$C$3:$C$175,$I37) | D37: =C37/100000 | G37: Technology | H37: Safety API | I37: 2. Driving Behavior & Risk Modeling
A38: 3. MVP user Research & Feedback Loops | B38: Sub-activity | C38: =SUMIFS('Line Items'!$F$3:$F$175,'Line Items'!$A$3:$A$175,$G38,'Line Items'!$B$3:$B$175,$H38,'Line Items'!$C$3:$C$175,$I38) | D38: =C38/100000 | G38: Technology | H38: Safety API | I38: 3. MVP user Research & Feedback Loops
A39: Safekart | B39: Activity | C39: =SUMIFS('Line Items'!$F$3:$F$175,'Line Items'!$A$3:$A$175,$G39,'Line Items'!$B$3:$B$175,$H39) | D39: =C39/100000 | E39: =C39/$C$3 | G39: Technology | H39: Safekart
A40: 1. User research and scoping | B40: Sub-activity | C40: =SUMIFS('Line Items'!$F$3:$F$175,'Line Items'!$A$3:$A$175,$G40,'Line Items'!$B$3:$B$175,$H40,'Line Items'!$C$3:$C$175,$I40) | D40: =C40/100000 | G40: Technology | H40: Safekart | I40: 1. User research and scoping
...

Sheet By Vertical
A1: AOP 2026–27 · Summary by vertical
A2: Vertical | B2: Budget (₹) | C2: In lacs | D2: % of AOP
A3: Policy | B3: =SUMIF('Line Items'!$A$3:$A$175,A3,'Line Items'!$F$3:$F$175) | C3: =B3/100000 | D3: =B3/$B$11
A4: Infrastructure | B4: =SUMIF('Line Items'!$A$3:$A$175,A4,'Line Items'!$F$3:$F$175) | C4: =B4/100000 | D4: =B4/$B$11
A5: Technology | B5: =SUMIF('Line Items'!$A$3:$A$175,A5,'Line Items'!$F$3:$F$175) | C5: =B5/100000 | D5: =B5/$B$11
A6: Post-emergency care | B6: =SUMIF('Line Items'!$A$3:$A$175,A6,'Line Items'!$F$3:$F$175) | C6: =B6/100000 | D6: =B6/$B$11
A7: Education | B7: =SUMIF('Line Items'!$A$3:$A$175,A7,'Line Items'!$F$3:$F$175) | C7: =B7/100000 | D7: =B7/$B$11
A8: Enabler - Research, Innovation and Community Mobilization | B8: =SUMIF('Line Items'!$A$3:$A$175,A8,'Line Items'!$F$3:$F$175) | C8: =B8/100000 | D8: =B8/$B$11
A9: Trust Admin | B9: =SUMIF('Line Items'!$A$3:$A$175,A9,'Line Items'!$F$3:$F$175) | C9: =B9/100000 | D9: =B9/$B$11
A10: Contingency cost (4%) | B10: =SUMIF('Line Items'!$A$3:$A$175,A10,'Line Items'!$F$3:$F$175) | C10: =B10/100000 | D10: =B10/$B$11
A11: Grand Total | B11: =SUM(B3:B10) | C11: =B11/100000 | D11: =B11/$B$11

Sheet Line Items
A1: CFI · AOP 2026–27 · Budget line items (source of truth · 173 rows · ₹6.0 Cr)
A2: Vertical | B2: Activity | C2: Sub-Activity | D2: Budget Header | E2: Description | F2: Budget (₹) | G2: In lacs
A3: Policy | B3: Legal Resources for Victims in Vernacular Languages | C3: Part 1: Development of Legal Resource Guide | D3: Translation into Vernacular Languages | E3: 10 languages @ ₹10,000 each (proofreading included) (20 pager report with 8k-12k words, INR 1/word) | F3: 100000 | G3: =F3/100000
A4: Policy | B4: Legal Resources for Victims in Vernacular Languages | C4: Part 1: Development of Legal Resource Guide | D4: Audio-Visual Format Creation | E4: 5*10 languages - explainer videos/audio guides for different formats (regional dubbing) (50*5000) | F4: 250000 | G4: =F4/100000
A5: Policy | B5: Legal Resources for Victims in Vernacular Languages | C5: Part 1: Development of Legal Resource Guide | D5: Printing Physical Copies | E5: 10,000 booklets, Handouts (~₹20/booklet incl. quality paper, color print) | F5: 200000 | G5: =F5/100000
A6: Policy | B6: Legal Resources for Victims in Vernacular Languages | C6: Part 1: Development of Legal Resource Guide | D6: Legal writers and researchers | E6: Legal writers + researchers to draft content in simple language (compensation, rights, procedures) (2 writers*25000*3 months) | F6: 150000 | G6: =F6/100000
A7: Policy | B7: Legal Resources for Victims in Vernacular Languages | C7: Part 1: Development of Legal Resource Guide | D7: Graphic Design + Layout (Comic strips, Doodling) | E7: Comic strip designs, engaging animated video design (with story): 10 regional langauges | F7: 200000 | G7: =F7/100000
A8: Policy | B8: Legal Resources for Victims in Vernacular Languages | C8: Part 1: Development of Legal Resource Guide | D8: Expert review (2 hour roundtable event) | E8: 2 rountable review sessions with experts (lawyers, government authorites, civic leaders) | F8: 150000 | G8: =F8/100000
A9: Policy | B9: Legal Resources for Victims in Vernacular Languages | C9: Part 2: Outreach and Distribution | D9: Media engagement | E9: Marketing the content on digital platforms (Influencer partnerships, Partnership with Policybazar, Uber, Ola, blinkit, Zepto for In-app ads), mass broadcasting (Media and Digital advocacy) | F9: 800000 | G9: =F9/100000
A10: Policy | B10: Legal Resources for Victims in Vernacular Languages | C10: Part 2: Outreach and Distribution | D10: Core team travel for partnerships | E10: Partnerships with Media, Influencers, Policybazaar, Uber etc. | F10: 20000 | G10: =F10/100000
A11: Policy | B11: Legal Resources for Victims in Vernacular Languages | C11: Part 2: Outreach and Distribution | D11: Resource Kits for Hospitals | E11: 500 kits @ ₹500 each (includes booklets, posters, QR codes, standees, explainer cards) | F11: 250000 | G11: =F11/100000
A12: Policy | B12: Legal Resources for Victims in Vernacular Languages | C12: Part 2: Outreach and Distribution | D12: Local Distribution Logistics | E12: Printing of booklets, comic strips to share with government authorities, expert panel, Transport, courier (250*200) | F12: 50000 | G12: =F12/100000
A13: Policy | B13: Legal Resources for Victims in Vernacular Languages | C13: Part 2: Outreach and Distribution | D13: MOUs with Hospitals/Trauma Centers | E13: Travel, Coordination with 15–20 hospitals; Staff briefings, onboarding, Guide distribution (15*10000) | F13: 150000 | G13: =F13/100000
A14: Policy | B14: Legal Resources for Victims in Vernacular Languages | C14: Part 3: Awareness Workshops & Law Camps | D14: Law Camps in Rural/Semi-urban Areas | E14: 4 camps x ₹150,000 (includes venue cost, tent, PA system, branding, refreshments) | F14: 600000 | G14: =F14/100000
... A175: Contingency cost (4%) | B175: Contingency cost (4%) | C175: Contingency cost (4%) | D175: Contingency cost (4%) | E175: Contingency cost (4%) | F175: 2400000 | G175: =F175/100000
A176: Grand Total | F176: =SUM(F3:F175) | G176: =F176/100000
