Workbook

Sheet 3-Level Bifurcation
A1: CFI · AOP 2026–27 · 3-level budget bifurcation (Vertical › Activity › Cost line · ₹6.00 Cr)
A2: Particulars | B2: Level | C2: Budget (₹) | D2: In lacs | E2: % of AOP | F2: Description / basis
A3: TOTAL — Annual Operating Plan 2026–27 (₹6.00 Cr) | C3: =C4+C23+C36+C47+C58+C65+C81 | D3: =C3/100000 | E3: =C3/$C$3 | F3: 71% into programmes · 25% backbone · 4% contingency
A4: Project Rakshak | B4: Vertical | C4: =C5+C9+C12+C14+C17+C19 | D4: =C4/100000 | E4: =C4/$C$3 | F4: Core programme · audit-to-implementation pipeline
A5: Institutional track (IIT / NIT / SPA teams) | B5: Activity | C5: =SUM(C6:C8) | D5: =C5/100000 | E5: =C5/$C$3
A6: Student team stipends | B6: Cost line | C6: 3240000 | D6: =C6/100000 | F6: ₹36,000 per team on completion · ~90 institutional sites
A7: Expert mentor honoraria | B7: Cost line | C7: 1300000 | D7: =C7/100000 | F7: Faculty & road-safety expert mentors across the cohort
A8: Campus outreach, onboarding & merchandise | B8: Cost line | C8: 960000 | D8: =C8/100000 | F8: Chapter mobilisation, IDs, kits
A9: NGO partner track (~20 sites) | B9: Activity | C9: =SUM(C10:C11) | D9: =C9/100000 | E9: =C9/$C$3
A10: NGO field-team engagement | B10: Cost line | C10: 2000000 | D10: =C10/100000 | F10: Field audits via NGO partners
A11: CFI desk + 10–15% physical re-checks | B11: Cost line | C11: 500000 | D11: =C11/100000 | F11: QA on NGO submissions
A12: Certified RSA track (~40 sites) | B12: Activity | C12: =SUM(C13:C13) | D12: =C12/100000 | E12: =C12/$C$3
A13: CRRI-certified auditor fees (IRC SP:88) | B13: Cost line | C13: 4500000 | D13: =C13/100000 | F13: Full audits usable by NHAI without rework
A14: Expert Consortium & Audit Manual v1.0 | B14: Activity | C14: =SUM(C15:C16) | D14: =C14/100000 | E14: =C14/$C$3
A15: Expert Consortium (4 meetings) | B15: Cost line | C15: 1000000 | D15: =C15/100000 | F15: Sep / Dec / Mar / Jun sittings
A16: Audit Manual v1.0 production | B16: Cost line | C16: 800000 | D16: =C16/100000 | F16: Authoring, design, print
A17: Public accountability dashboard | B17: Activity | C17: =SUM(C18:C18) | D17: =C17/100000 | E17: =C17/$C$3
A18: Dashboard build, hosting & maintenance | B18: Cost line | C18: 1200000 | D18: =C18/100000 | F18: Identification → audit → review → implementation tracker
A19: Programme management & field ops | B19: Activity | C19: =SUM(C20:C22) | D19: =C19/100000 | E19: =C19/$C$3
A20: Programme management (staff allocation) | B20: Cost line | C20: 1800000 | D20: =C20/100000 | F20: PM + coordination
A21: Field travel & logistics | B21: Cost line | C21: 700000 | D21: =C21/100000 | F21: Site visits, DRSC meetings
A22: National forum & DRSC presentations | B22: Cost line | C22: 500000 | D22: =C22/100000 | F22: 12+ DRSC presentations, year-end forum
A23: Hit & Run Compensation | B23: Vertical | C23: =C24+C27+C30+C33 | D23: =C23/100000 | E23: =C23/$C$3 | F23: Core programme · fix two districts, map eight
A24: Scheme audit & process documentation | B24: Activity | C24: =SUM(C25:C26) | D24: =C24/100000 | E24: =C24/$C$3
A25: Stage-wise pipeline audit fieldwork (Gurugram) | B25: Cost line | C25: 1200000 | D25: =C25/100000 | F25: FIR → GI Council disbursal; 20–30 claims tracked end-to-end
A26: 'Where the Pipeline Breaks' report | B26: Cost line | C26: 600000 | D26: =C26/100000 | F26: Scheme audit submitted to MoRTH
A27: Institutional capacity building | B27: Activity | C27: =SUM(C28:C29) | D27: =C27/100000 | E27: =C27/$C$3
A28: Fellow-in-Residence stipend (Tehsildar office) | B28: Cost line | C28: 1200000 | D28: =C28/100000 | F28: Embedded fellow · research-embedded, not social work
A29: SOP reference cards & training-gap assessment | B29: Cost line | C29: 800000 | D29: =C29/100000 | F29: District capacity building
A30: Victim identification & AASHA | B30: Activity | C30: =SUM(C31:C32) | D30: =C30/100000 | E30: =C30/$C$3
A31: DLSA-partnered helpdesks | B31: Cost line | C31: 800000 | D31: =C31/100000 | F31: Trauma-ward legal helpdesks
A32: AASHA QR deployment | B32: Cost line | C32: 600000 | D32: =C32/100000 | F32: Police stations & trauma centres; usage measured monthly
A33: Policy audit & advocacy | B33: Activity | C33: =SUM(C34:C35) | D33: =C33/100000 | E33: =C33/$C$3
A34: Quarterly findings & public brief | B34: Cost line | C34: 500000 | D34: =C34/100000 | F34: Publishing cadence
A35: Advocacy & MoRTH engagement travel | B35: Cost line | C35: 300000 | D35: =C35/100000 | F35: Stakeholder engagement
A36: Civic & GovTech (SATARK) | B36: Vertical | C36: =C37+C41+C44 | D36: =C36/100000 | E36: =C36/$C$3 | F36: Core programme · enforcement co-pilot + data stack
A37: SATARK scale to 30 cities | B37: Activity | C37: =SUM(C38:C40) | D37: =C37/100000 | E37: =C37/$C$3
A38: SATARK engineering & product | B38: Cost line | C38: 2500000 | D38: =C38/100000 | F38: ANPR, ULIP, rule engine, billboard + officer app
A39: City deployment & rollout | B39: Cost line | C39: 2000000 | D39: =C39/100000 | F39: Toward 30 cities · Gurugram, Pune, Ahmedabad first
A40: Cloud, ANPR & ULIP integration | B40: Cost line | C40: 1500000 | D40: =C40/100000 | F40: Compute, APIs, camera integration
...

Sheet By Vertical
A1: AOP 2026–27 · Summary by vertical (Level 1)
A2: Vertical | B2: Budget (₹) | C2: In lacs | D2: % of AOP
A3: Project Rakshak | B3: ='3-Level Bifurcation'!C4 | C3: =B3/100000 | D3: =B3/$B$10
A4: Hit & Run Compensation | B4: ='3-Level Bifurcation'!C23 | C4: =B4/100000 | D4: =B4/$B$10
A5: Civic & GovTech (SATARK) | B5: ='3-Level Bifurcation'!C36 | C5: =B5/100000 | D5: =B5/$B$10
A6: Marketing Campaign | B6: ='3-Level Bifurcation'!C47 | C6: =B6/100000 | D6: =B6/$B$10
A7: Bets (SSI + Gig Rider) | B7: ='3-Level Bifurcation'!C58 | C7: =B7/100000 | D7: =B7/$B$10
A8: Trust Admin (Org Backbone) | B8: ='3-Level Bifurcation'!C65 | C8: =B8/100000 | D8: =B8/$B$10
A9: Contingency (4%) | B9: ='3-Level Bifurcation'!C81 | C9: =B9/100000 | D9: =B9/$B$10
A10: Grand Total | B10: =SUM(B3:B9) | C10: =B10/100000 | D10: =B10/$B$10

Sheet Notes & basis
A1: CFI · AOP 2026–27 — 3-level bifurcation · basis & assumptions
A3: EXACT (from the board-approved AOP, 'From programmes to institutions'):
A4: • The 7 Level-1 verticals and their totals: Rakshak ₹1.85 Cr · Hit & Run ₹0.60 Cr · Civic & GovTech (SATARK) ₹1.00 Cr ·
A5: Marketing Campaign ₹0.60 Cr · Bets ₹0.20 Cr · Trust Admin ₹1.51 Cr · Contingency ₹0.24 Cr = ₹6.00 Cr.
A6: • Trust Admin's five headers (salaries ₹0.78 Cr, IRSC support ₹0.42 Cr, IT/SaaS/AI ₹0.14 Cr, M&E ₹0.06 Cr,
A7: travel/branding/compliance ₹0.11 Cr) are taken verbatim from the org-backbone slide.
A9: FIRST-PASS (designed by me to sum exactly to each vertical — edit freely, everything rolls up):
A10: • All Level-2 activities and Level-3 cost lines inside the programmes (Rakshak, Hit & Run, SATARK, Campaign, Bets).
A11: • The salaries split into core staff (₹42 L) vs SMIF fellowship (₹36 L) within the ₹0.78 Cr salaries line.
A12: • The itemisation of the ₹0.14 Cr IT/SaaS/AI tooling line into individual tools.
A14: FELLOW COSTS kept visible, as requested (marked ★):
A15: • Rakshak — Student team stipends: ₹36,000 per team on completion (~90 institutional sites) [confirmed in Slack].
... A26: #cfi-core, #builders-cfi · Gmail (Anthropic receipts, SMIF fellowship, Codex request).
